2025-04-14 22:24:40,279 ERROR /home/igoriusha/.virtualenvs/.venv/lib/python3.12/site-packages/django/utils/log.py (<class 'django.db.utils.ProgrammingError'>, ProgrammingError('column news_post.image does not exist\nLINE 1: ..._post"."time_in_post", "news_post"."rating_post", "news_post...\n                                                             ^\n'), <traceback object at 0x7327766cdf00>) Internal Server Error: /admin/news/comment/
Traceback (most recent call last):
  File "/home/igoriusha/.virtualenvs/.venv/lib/python3.12/site-packages/django/db/models/options.py", line 676, in get_field
    return self.fields_map[field_name]
           ~~~~~~~~~~~~~~~^^^^^^^^^^^^
KeyError: 'name_post'

During handling of the above exception, another exception occurred:

Traceback (most recent call last):
  File "/home/igoriusha/.virtualenvs/.venv/lib/python3.12/site-packages/django/contrib/admin/utils.py", line 290, in lookup_field
    f = _get_non_gfk_field(opts, name)
        ^^^^^^^^^^^^^^^^^^^^^^^^^^^^^^
  File "/home/igoriusha/.virtualenvs/.venv/lib/python3.12/site-packages/django/contrib/admin/utils.py", line 330, in _get_non_gfk_field
    field = opts.get_field(name)
            ^^^^^^^^^^^^^^^^^^^^
  File "/home/igoriusha/.virtualenvs/.venv/lib/python3.12/site-packages/django/db/models/options.py", line 678, in get_field
    raise FieldDoesNotExist(
django.core.exceptions.FieldDoesNotExist: Comment has no field named 'name_post'

During handling of the above exception, another exception occurred:

Traceback (most recent call last):
  File "/home/igoriusha/.virtualenvs/.venv/lib/python3.12/site-packages/django/db/models/fields/related_descriptors.py", line 239, in __get__
    rel_obj = self.field.get_cached_value(instance)
              ^^^^^^^^^^^^^^^^^^^^^^^^^^^^^^^^^^^^^
  File "/home/igoriusha/.virtualenvs/.venv/lib/python3.12/site-packages/django/db/models/fields/mixins.py", line 37, in get_cached_value
    return instance._state.fields_cache[self.cache_name]
           ~~~~~~~~~~~~~~~~~~~~~~~~~~~~^^^^^^^^^^^^^^^^^
KeyError: 'post_comment'

During handling of the above exception, another exception occurred:

Traceback (most recent call last):
  File "/home/igoriusha/.virtualenvs/.venv/lib/python3.12/site-packages/django/db/backends/utils.py", line 105, in _execute
    return self.cursor.execute(sql, params)
           ^^^^^^^^^^^^^^^^^^^^^^^^^^^^^^^^
psycopg2.errors.UndefinedColumn: column news_post.image does not exist
LINE 1: ..._post"."time_in_post", "news_post"."rating_post", "news_post...
                                                             ^


The above exception was the direct cause of the following exception:

Traceback (most recent call last):
  File "/home/igoriusha/.virtualenvs/.venv/lib/python3.12/site-packages/django/core/handlers/exception.py", line 55, in inner
    response = get_response(request)
               ^^^^^^^^^^^^^^^^^^^^^
  File "/home/igoriusha/.virtualenvs/.venv/lib/python3.12/site-packages/django/core/handlers/base.py", line 220, in _get_response
    response = response.render()
               ^^^^^^^^^^^^^^^^^
  File "/home/igoriusha/.virtualenvs/.venv/lib/python3.12/site-packages/django/template/response.py", line 114, in render
    self.content = self.rendered_content
                   ^^^^^^^^^^^^^^^^^^^^^
  File "/home/igoriusha/.virtualenvs/.venv/lib/python3.12/site-packages/django/template/response.py", line 92, in rendered_content
    return template.render(context, self._request)
           ^^^^^^^^^^^^^^^^^^^^^^^^^^^^^^^^^^^^^^^
  File "/home/igoriusha/.virtualenvs/.venv/lib/python3.12/site-packages/django/template/backends/django.py", line 107, in render
    return self.template.render(context)
           ^^^^^^^^^^^^^^^^^^^^^^^^^^^^^
  File "/home/igoriusha/.virtualenvs/.venv/lib/python3.12/site-packages/django/template/base.py", line 171, in render
    return self._render(context)
           ^^^^^^^^^^^^^^^^^^^^^
  File "/home/igoriusha/.virtualenvs/.venv/lib/python3.12/site-packages/django/template/base.py", line 163, in _render
    return self.nodelist.render(context)
           ^^^^^^^^^^^^^^^^^^^^^^^^^^^^^
  File "/home/igoriusha/.virtualenvs/.venv/lib/python3.12/site-packages/django/template/base.py", line 1008, in render
    return SafeString("".join([node.render_annotated(context) for node in self]))
                               ^^^^^^^^^^^^^^^^^^^^^^^^^^^^^^
  File "/home/igoriusha/.virtualenvs/.venv/lib/python3.12/site-packages/django/template/base.py", line 969, in render_annotated
    return self.render(context)
           ^^^^^^^^^^^^^^^^^^^^
  File "/home/igoriusha/.virtualenvs/.venv/lib/python3.12/site-packages/django/template/loader_tags.py", line 159, in render
    return compiled_parent._render(context)
           ^^^^^^^^^^^^^^^^^^^^^^^^^^^^^^^^
  File "/home/igoriusha/.virtualenvs/.venv/lib/python3.12/site-packages/django/template/base.py", line 163, in _render
    return self.nodelist.render(context)
           ^^^^^^^^^^^^^^^^^^^^^^^^^^^^^
  File "/home/igoriusha/.virtualenvs/.venv/lib/python3.12/site-packages/django/template/base.py", line 1008, in render
    return SafeString("".join([node.render_annotated(context) for node in self]))
                               ^^^^^^^^^^^^^^^^^^^^^^^^^^^^^^
  File "/home/igoriusha/.virtualenvs/.venv/lib/python3.12/site-packages/django/template/base.py", line 969, in render_annotated
    return self.render(context)
           ^^^^^^^^^^^^^^^^^^^^
  File "/home/igoriusha/.virtualenvs/.venv/lib/python3.12/site-packages/django/template/loader_tags.py", line 159, in render
    return compiled_parent._render(context)
           ^^^^^^^^^^^^^^^^^^^^^^^^^^^^^^^^
  File "/home/igoriusha/.virtualenvs/.venv/lib/python3.12/site-packages/django/template/base.py", line 163, in _render
    return self.nodelist.render(context)
           ^^^^^^^^^^^^^^^^^^^^^^^^^^^^^
  File "/home/igoriusha/.virtualenvs/.venv/lib/python3.12/site-packages/django/template/base.py", line 1008, in render
    return SafeString("".join([node.render_annotated(context) for node in self]))
                               ^^^^^^^^^^^^^^^^^^^^^^^^^^^^^^
  File "/home/igoriusha/.virtualenvs/.venv/lib/python3.12/site-packages/django/template/base.py", line 969, in render_annotated
    return self.render(context)
           ^^^^^^^^^^^^^^^^^^^^
  File "/home/igoriusha/.virtualenvs/.venv/lib/python3.12/site-packages/django/template/loader_tags.py", line 65, in render
    result = block.nodelist.render(context)
             ^^^^^^^^^^^^^^^^^^^^^^^^^^^^^^
  File "/home/igoriusha/.virtualenvs/.venv/lib/python3.12/site-packages/django/template/base.py", line 1008, in render
    return SafeString("".join([node.render_annotated(context) for node in self]))
                               ^^^^^^^^^^^^^^^^^^^^^^^^^^^^^^
  File "/home/igoriusha/.virtualenvs/.venv/lib/python3.12/site-packages/django/template/base.py", line 969, in render_annotated
    return self.render(context)
           ^^^^^^^^^^^^^^^^^^^^
  File "/home/igoriusha/.virtualenvs/.venv/lib/python3.12/site-packages/django/template/loader_tags.py", line 65, in render
    result = block.nodelist.render(context)
             ^^^^^^^^^^^^^^^^^^^^^^^^^^^^^^
  File "/home/igoriusha/.virtualenvs/.venv/lib/python3.12/site-packages/django/template/base.py", line 1008, in render
    return SafeString("".join([node.render_annotated(context) for node in self]))
                               ^^^^^^^^^^^^^^^^^^^^^^^^^^^^^^
  File "/home/igoriusha/.virtualenvs/.venv/lib/python3.12/site-packages/django/template/base.py", line 969, in render_annotated
    return self.render(context)
           ^^^^^^^^^^^^^^^^^^^^
  File "/home/igoriusha/.virtualenvs/.venv/lib/python3.12/site-packages/django/contrib/admin/templatetags/base.py", line 45, in render
    return super().render(context)
           ^^^^^^^^^^^^^^^^^^^^^^^
  File "/home/igoriusha/.virtualenvs/.venv/lib/python3.12/site-packages/django/template/library.py", line 258, in render
    _dict = self.func(*resolved_args, **resolved_kwargs)
            ^^^^^^^^^^^^^^^^^^^^^^^^^^^^^^^^^^^^^^^^^^^^
  File "/home/igoriusha/.virtualenvs/.venv/lib/python3.12/site-packages/django/contrib/admin/templatetags/admin_list.py", line 346, in result_list
    "results": list(results(cl)),
               ^^^^^^^^^^^^^^^^^
  File "/home/igoriusha/.virtualenvs/.venv/lib/python3.12/site-packages/django/contrib/admin/templatetags/admin_list.py", line 322, in results
    yield ResultList(None, items_for_result(cl, res, None))
          ^^^^^^^^^^^^^^^^^^^^^^^^^^^^^^^^^^^^^^^^^^^^^^^^^
  File "/home/igoriusha/.virtualenvs/.venv/lib/python3.12/site-packages/django/contrib/admin/templatetags/admin_list.py", line 313, in __init__
    super().__init__(*items)
  File "/home/igoriusha/.virtualenvs/.venv/lib/python3.12/site-packages/django/contrib/admin/templatetags/admin_list.py", line 218, in items_for_result
    f, attr, value = lookup_field(field_name, result, cl.model_admin)
                     ^^^^^^^^^^^^^^^^^^^^^^^^^^^^^^^^^^^^^^^^^^^^^^^^
  File "/home/igoriusha/.virtualenvs/.venv/lib/python3.12/site-packages/django/contrib/admin/utils.py", line 299, in lookup_field
    value = attr(obj)
            ^^^^^^^^^
  File "/home/igoriusha/MyProject/Portal_News/NewsPaper/news/admin.py", line 280, in name_post
    return obj.preview(obj.post_comment.title_post)
                       ^^^^^^^^^^^^^^^^
  File "/home/igoriusha/.virtualenvs/.venv/lib/python3.12/site-packages/django/db/models/fields/related_descriptors.py", line 257, in __get__
    rel_obj = self.get_object(instance)
              ^^^^^^^^^^^^^^^^^^^^^^^^^
  File "/home/igoriusha/.virtualenvs/.venv/lib/python3.12/site-packages/django/db/models/fields/related_descriptors.py", line 220, in get_object
    return qs.get(self.field.get_reverse_related_filter(instance))
           ^^^^^^^^^^^^^^^^^^^^^^^^^^^^^^^^^^^^^^^^^^^^^^^^^^^^^^^
  File "/home/igoriusha/.virtualenvs/.venv/lib/python3.12/site-packages/django/db/models/query.py", line 645, in get
    num = len(clone)
          ^^^^^^^^^^
  File "/home/igoriusha/.virtualenvs/.venv/lib/python3.12/site-packages/django/db/models/query.py", line 382, in __len__
    self._fetch_all()
  File "/home/igoriusha/.virtualenvs/.venv/lib/python3.12/site-packages/django/db/models/query.py", line 1928, in _fetch_all
    self._result_cache = list(self._iterable_class(self))
                         ^^^^^^^^^^^^^^^^^^^^^^^^^^^^^^^^
  File "/home/igoriusha/.virtualenvs/.venv/lib/python3.12/site-packages/django/db/models/query.py", line 91, in __iter__
    results = compiler.execute_sql(
              ^^^^^^^^^^^^^^^^^^^^^
  File "/home/igoriusha/.virtualenvs/.venv/lib/python3.12/site-packages/django/db/models/sql/compiler.py", line 1574, in execute_sql
    cursor.execute(sql, params)
  File "/home/igoriusha/.virtualenvs/.venv/lib/python3.12/site-packages/django/db/backends/utils.py", line 79, in execute
    return self._execute_with_wrappers(
           ^^^^^^^^^^^^^^^^^^^^^^^^^^^^
  File "/home/igoriusha/.virtualenvs/.venv/lib/python3.12/site-packages/django/db/backends/utils.py", line 92, in _execute_with_wrappers
    return executor(sql, params, many, context)
           ^^^^^^^^^^^^^^^^^^^^^^^^^^^^^^^^^^^^
  File "/home/igoriusha/.virtualenvs/.venv/lib/python3.12/site-packages/django/db/backends/utils.py", line 100, in _execute
    with self.db.wrap_database_errors:
  File "/home/igoriusha/.virtualenvs/.venv/lib/python3.12/site-packages/django/db/utils.py", line 91, in __exit__
    raise dj_exc_value.with_traceback(traceback) from exc_value
  File "/home/igoriusha/.virtualenvs/.venv/lib/python3.12/site-packages/django/db/backends/utils.py", line 105, in _execute
    return self.cursor.execute(sql, params)
           ^^^^^^^^^^^^^^^^^^^^^^^^^^^^^^^^
django.db.utils.ProgrammingError: column news_post.image does not exist
LINE 1: ..._post"."time_in_post", "news_post"."rating_post", "news_post...
                                                             ^

2025-04-14 22:24:40,298 ERROR /home/igoriusha/.virtualenvs/.venv/lib/python3.12/site-packages/django/core/servers/basehttp.py None "GET /admin/news/comment/ HTTP/1.1" 500 7527
2025-04-14 22:24:59,858 ERROR /home/igoriusha/.virtualenvs/.venv/lib/python3.12/site-packages/django/utils/log.py (<class 'django.db.utils.ProgrammingError'>, ProgrammingError('column news_post.image does not exist\nLINE 1: ..._post"."time_in_post", "news_post"."rating_post", "news_post...\n                                                             ^\n'), <traceback object at 0x7327768a2900>) Internal Server Error: /admin/news/comment/
Traceback (most recent call last):
  File "/home/igoriusha/.virtualenvs/.venv/lib/python3.12/site-packages/django/db/models/options.py", line 676, in get_field
    return self.fields_map[field_name]
           ~~~~~~~~~~~~~~~^^^^^^^^^^^^
KeyError: 'name_post'

During handling of the above exception, another exception occurred:

Traceback (most recent call last):
  File "/home/igoriusha/.virtualenvs/.venv/lib/python3.12/site-packages/django/contrib/admin/utils.py", line 290, in lookup_field
    f = _get_non_gfk_field(opts, name)
        ^^^^^^^^^^^^^^^^^^^^^^^^^^^^^^
  File "/home/igoriusha/.virtualenvs/.venv/lib/python3.12/site-packages/django/contrib/admin/utils.py", line 330, in _get_non_gfk_field
    field = opts.get_field(name)
            ^^^^^^^^^^^^^^^^^^^^
  File "/home/igoriusha/.virtualenvs/.venv/lib/python3.12/site-packages/django/db/models/options.py", line 678, in get_field
    raise FieldDoesNotExist(
django.core.exceptions.FieldDoesNotExist: Comment has no field named 'name_post'

During handling of the above exception, another exception occurred:

Traceback (most recent call last):
  File "/home/igoriusha/.virtualenvs/.venv/lib/python3.12/site-packages/django/db/models/fields/related_descriptors.py", line 239, in __get__
    rel_obj = self.field.get_cached_value(instance)
              ^^^^^^^^^^^^^^^^^^^^^^^^^^^^^^^^^^^^^
  File "/home/igoriusha/.virtualenvs/.venv/lib/python3.12/site-packages/django/db/models/fields/mixins.py", line 37, in get_cached_value
    return instance._state.fields_cache[self.cache_name]
           ~~~~~~~~~~~~~~~~~~~~~~~~~~~~^^^^^^^^^^^^^^^^^
KeyError: 'post_comment'

During handling of the above exception, another exception occurred:

Traceback (most recent call last):
  File "/home/igoriusha/.virtualenvs/.venv/lib/python3.12/site-packages/django/db/backends/utils.py", line 105, in _execute
    return self.cursor.execute(sql, params)
           ^^^^^^^^^^^^^^^^^^^^^^^^^^^^^^^^
psycopg2.errors.UndefinedColumn: column news_post.image does not exist
LINE 1: ..._post"."time_in_post", "news_post"."rating_post", "news_post...
                                                             ^


The above exception was the direct cause of the following exception:

Traceback (most recent call last):
  File "/home/igoriusha/.virtualenvs/.venv/lib/python3.12/site-packages/django/core/handlers/exception.py", line 55, in inner
    response = get_response(request)
               ^^^^^^^^^^^^^^^^^^^^^
  File "/home/igoriusha/.virtualenvs/.venv/lib/python3.12/site-packages/django/core/handlers/base.py", line 220, in _get_response
    response = response.render()
               ^^^^^^^^^^^^^^^^^
  File "/home/igoriusha/.virtualenvs/.venv/lib/python3.12/site-packages/django/template/response.py", line 114, in render
    self.content = self.rendered_content
                   ^^^^^^^^^^^^^^^^^^^^^
  File "/home/igoriusha/.virtualenvs/.venv/lib/python3.12/site-packages/django/template/response.py", line 92, in rendered_content
    return template.render(context, self._request)
           ^^^^^^^^^^^^^^^^^^^^^^^^^^^^^^^^^^^^^^^
  File "/home/igoriusha/.virtualenvs/.venv/lib/python3.12/site-packages/django/template/backends/django.py", line 107, in render
    return self.template.render(context)
           ^^^^^^^^^^^^^^^^^^^^^^^^^^^^^
  File "/home/igoriusha/.virtualenvs/.venv/lib/python3.12/site-packages/django/template/base.py", line 171, in render
    return self._render(context)
           ^^^^^^^^^^^^^^^^^^^^^
  File "/home/igoriusha/.virtualenvs/.venv/lib/python3.12/site-packages/django/template/base.py", line 163, in _render
    return self.nodelist.render(context)
           ^^^^^^^^^^^^^^^^^^^^^^^^^^^^^
  File "/home/igoriusha/.virtualenvs/.venv/lib/python3.12/site-packages/django/template/base.py", line 1008, in render
    return SafeString("".join([node.render_annotated(context) for node in self]))
                               ^^^^^^^^^^^^^^^^^^^^^^^^^^^^^^
  File "/home/igoriusha/.virtualenvs/.venv/lib/python3.12/site-packages/django/template/base.py", line 969, in render_annotated
    return self.render(context)
           ^^^^^^^^^^^^^^^^^^^^
  File "/home/igoriusha/.virtualenvs/.venv/lib/python3.12/site-packages/django/template/loader_tags.py", line 159, in render
    return compiled_parent._render(context)
           ^^^^^^^^^^^^^^^^^^^^^^^^^^^^^^^^
  File "/home/igoriusha/.virtualenvs/.venv/lib/python3.12/site-packages/django/template/base.py", line 163, in _render
    return self.nodelist.render(context)
           ^^^^^^^^^^^^^^^^^^^^^^^^^^^^^
  File "/home/igoriusha/.virtualenvs/.venv/lib/python3.12/site-packages/django/template/base.py", line 1008, in render
    return SafeString("".join([node.render_annotated(context) for node in self]))
                               ^^^^^^^^^^^^^^^^^^^^^^^^^^^^^^
  File "/home/igoriusha/.virtualenvs/.venv/lib/python3.12/site-packages/django/template/base.py", line 969, in render_annotated
    return self.render(context)
           ^^^^^^^^^^^^^^^^^^^^
  File "/home/igoriusha/.virtualenvs/.venv/lib/python3.12/site-packages/django/template/loader_tags.py", line 159, in render
    return compiled_parent._render(context)
           ^^^^^^^^^^^^^^^^^^^^^^^^^^^^^^^^
  File "/home/igoriusha/.virtualenvs/.venv/lib/python3.12/site-packages/django/template/base.py", line 163, in _render
    return self.nodelist.render(context)
           ^^^^^^^^^^^^^^^^^^^^^^^^^^^^^
  File "/home/igoriusha/.virtualenvs/.venv/lib/python3.12/site-packages/django/template/base.py", line 1008, in render
    return SafeString("".join([node.render_annotated(context) for node in self]))
                               ^^^^^^^^^^^^^^^^^^^^^^^^^^^^^^
  File "/home/igoriusha/.virtualenvs/.venv/lib/python3.12/site-packages/django/template/base.py", line 969, in render_annotated
    return self.render(context)
           ^^^^^^^^^^^^^^^^^^^^
  File "/home/igoriusha/.virtualenvs/.venv/lib/python3.12/site-packages/django/template/loader_tags.py", line 65, in render
    result = block.nodelist.render(context)
             ^^^^^^^^^^^^^^^^^^^^^^^^^^^^^^
  File "/home/igoriusha/.virtualenvs/.venv/lib/python3.12/site-packages/django/template/base.py", line 1008, in render
    return SafeString("".join([node.render_annotated(context) for node in self]))
                               ^^^^^^^^^^^^^^^^^^^^^^^^^^^^^^
  File "/home/igoriusha/.virtualenvs/.venv/lib/python3.12/site-packages/django/template/base.py", line 969, in render_annotated
    return self.render(context)
           ^^^^^^^^^^^^^^^^^^^^
  File "/home/igoriusha/.virtualenvs/.venv/lib/python3.12/site-packages/django/template/loader_tags.py", line 65, in render
    result = block.nodelist.render(context)
             ^^^^^^^^^^^^^^^^^^^^^^^^^^^^^^
  File "/home/igoriusha/.virtualenvs/.venv/lib/python3.12/site-packages/django/template/base.py", line 1008, in render
    return SafeString("".join([node.render_annotated(context) for node in self]))
                               ^^^^^^^^^^^^^^^^^^^^^^^^^^^^^^
  File "/home/igoriusha/.virtualenvs/.venv/lib/python3.12/site-packages/django/template/base.py", line 969, in render_annotated
    return self.render(context)
           ^^^^^^^^^^^^^^^^^^^^
  File "/home/igoriusha/.virtualenvs/.venv/lib/python3.12/site-packages/django/contrib/admin/templatetags/base.py", line 45, in render
    return super().render(context)
           ^^^^^^^^^^^^^^^^^^^^^^^
  File "/home/igoriusha/.virtualenvs/.venv/lib/python3.12/site-packages/django/template/library.py", line 258, in render
    _dict = self.func(*resolved_args, **resolved_kwargs)
            ^^^^^^^^^^^^^^^^^^^^^^^^^^^^^^^^^^^^^^^^^^^^
  File "/home/igoriusha/.virtualenvs/.venv/lib/python3.12/site-packages/django/contrib/admin/templatetags/admin_list.py", line 346, in result_list
    "results": list(results(cl)),
               ^^^^^^^^^^^^^^^^^
  File "/home/igoriusha/.virtualenvs/.venv/lib/python3.12/site-packages/django/contrib/admin/templatetags/admin_list.py", line 322, in results
    yield ResultList(None, items_for_result(cl, res, None))
          ^^^^^^^^^^^^^^^^^^^^^^^^^^^^^^^^^^^^^^^^^^^^^^^^^
  File "/home/igoriusha/.virtualenvs/.venv/lib/python3.12/site-packages/django/contrib/admin/templatetags/admin_list.py", line 313, in __init__
    super().__init__(*items)
  File "/home/igoriusha/.virtualenvs/.venv/lib/python3.12/site-packages/django/contrib/admin/templatetags/admin_list.py", line 218, in items_for_result
    f, attr, value = lookup_field(field_name, result, cl.model_admin)
                     ^^^^^^^^^^^^^^^^^^^^^^^^^^^^^^^^^^^^^^^^^^^^^^^^
  File "/home/igoriusha/.virtualenvs/.venv/lib/python3.12/site-packages/django/contrib/admin/utils.py", line 299, in lookup_field
    value = attr(obj)
            ^^^^^^^^^
  File "/home/igoriusha/MyProject/Portal_News/NewsPaper/news/admin.py", line 280, in name_post
    return obj.preview(obj.post_comment.title_post)
                       ^^^^^^^^^^^^^^^^
  File "/home/igoriusha/.virtualenvs/.venv/lib/python3.12/site-packages/django/db/models/fields/related_descriptors.py", line 257, in __get__
    rel_obj = self.get_object(instance)
              ^^^^^^^^^^^^^^^^^^^^^^^^^
  File "/home/igoriusha/.virtualenvs/.venv/lib/python3.12/site-packages/django/db/models/fields/related_descriptors.py", line 220, in get_object
    return qs.get(self.field.get_reverse_related_filter(instance))
           ^^^^^^^^^^^^^^^^^^^^^^^^^^^^^^^^^^^^^^^^^^^^^^^^^^^^^^^
  File "/home/igoriusha/.virtualenvs/.venv/lib/python3.12/site-packages/django/db/models/query.py", line 645, in get
    num = len(clone)
          ^^^^^^^^^^
  File "/home/igoriusha/.virtualenvs/.venv/lib/python3.12/site-packages/django/db/models/query.py", line 382, in __len__
    self._fetch_all()
  File "/home/igoriusha/.virtualenvs/.venv/lib/python3.12/site-packages/django/db/models/query.py", line 1928, in _fetch_all
    self._result_cache = list(self._iterable_class(self))
                         ^^^^^^^^^^^^^^^^^^^^^^^^^^^^^^^^
  File "/home/igoriusha/.virtualenvs/.venv/lib/python3.12/site-packages/django/db/models/query.py", line 91, in __iter__
    results = compiler.execute_sql(
              ^^^^^^^^^^^^^^^^^^^^^
  File "/home/igoriusha/.virtualenvs/.venv/lib/python3.12/site-packages/django/db/models/sql/compiler.py", line 1574, in execute_sql
    cursor.execute(sql, params)
  File "/home/igoriusha/.virtualenvs/.venv/lib/python3.12/site-packages/django/db/backends/utils.py", line 79, in execute
    return self._execute_with_wrappers(
           ^^^^^^^^^^^^^^^^^^^^^^^^^^^^
  File "/home/igoriusha/.virtualenvs/.venv/lib/python3.12/site-packages/django/db/backends/utils.py", line 92, in _execute_with_wrappers
    return executor(sql, params, many, context)
           ^^^^^^^^^^^^^^^^^^^^^^^^^^^^^^^^^^^^
  File "/home/igoriusha/.virtualenvs/.venv/lib/python3.12/site-packages/django/db/backends/utils.py", line 100, in _execute
    with self.db.wrap_database_errors:
  File "/home/igoriusha/.virtualenvs/.venv/lib/python3.12/site-packages/django/db/utils.py", line 91, in __exit__
    raise dj_exc_value.with_traceback(traceback) from exc_value
  File "/home/igoriusha/.virtualenvs/.venv/lib/python3.12/site-packages/django/db/backends/utils.py", line 105, in _execute
    return self.cursor.execute(sql, params)
           ^^^^^^^^^^^^^^^^^^^^^^^^^^^^^^^^
django.db.utils.ProgrammingError: column news_post.image does not exist
LINE 1: ..._post"."time_in_post", "news_post"."rating_post", "news_post...
                                                             ^

2025-04-14 22:24:59,864 ERROR /home/igoriusha/.virtualenvs/.venv/lib/python3.12/site-packages/django/core/servers/basehttp.py None "GET /admin/news/comment/ HTTP/1.1" 500 7527
2025-04-14 22:25:07,368 ERROR /home/igoriusha/.virtualenvs/.venv/lib/python3.12/site-packages/django/utils/log.py (<class 'django.db.utils.ProgrammingError'>, ProgrammingError('column news_post.image does not exist\nLINE 1: ..._post"."time_in_post", "news_post"."rating_post", "news_post...\n                                                             ^\n'), <traceback object at 0x732776748ec0>) Internal Server Error: /admin/news/post/
Traceback (most recent call last):
  File "/home/igoriusha/.virtualenvs/.venv/lib/python3.12/site-packages/django/db/backends/utils.py", line 105, in _execute
    return self.cursor.execute(sql, params)
           ^^^^^^^^^^^^^^^^^^^^^^^^^^^^^^^^
psycopg2.errors.UndefinedColumn: column news_post.image does not exist
LINE 1: ..._post"."time_in_post", "news_post"."rating_post", "news_post...
                                                             ^


The above exception was the direct cause of the following exception:

Traceback (most recent call last):
  File "/home/igoriusha/.virtualenvs/.venv/lib/python3.12/site-packages/django/core/handlers/exception.py", line 55, in inner
    response = get_response(request)
               ^^^^^^^^^^^^^^^^^^^^^
  File "/home/igoriusha/.virtualenvs/.venv/lib/python3.12/site-packages/django/core/handlers/base.py", line 197, in _get_response
    response = wrapped_callback(request, *callback_args, **callback_kwargs)
               ^^^^^^^^^^^^^^^^^^^^^^^^^^^^^^^^^^^^^^^^^^^^^^^^^^^^^^^^^^^^
  File "/home/igoriusha/.virtualenvs/.venv/lib/python3.12/site-packages/django/contrib/admin/options.py", line 718, in wrapper
    return self.admin_site.admin_view(view)(*args, **kwargs)
           ^^^^^^^^^^^^^^^^^^^^^^^^^^^^^^^^^^^^^^^^^^^^^^^^^
  File "/home/igoriusha/.virtualenvs/.venv/lib/python3.12/site-packages/django/utils/decorators.py", line 188, in _view_wrapper
    result = _process_exception(request, e)
             ^^^^^^^^^^^^^^^^^^^^^^^^^^^^^^
  File "/home/igoriusha/.virtualenvs/.venv/lib/python3.12/site-packages/django/utils/decorators.py", line 186, in _view_wrapper
    response = view_func(request, *args, **kwargs)
               ^^^^^^^^^^^^^^^^^^^^^^^^^^^^^^^^^^^
  File "/home/igoriusha/.virtualenvs/.venv/lib/python3.12/site-packages/django/views/decorators/cache.py", line 80, in _view_wrapper
    response = view_func(request, *args, **kwargs)
               ^^^^^^^^^^^^^^^^^^^^^^^^^^^^^^^^^^^
  File "/home/igoriusha/.virtualenvs/.venv/lib/python3.12/site-packages/django/contrib/admin/sites.py", line 241, in inner
    return view(request, *args, **kwargs)
           ^^^^^^^^^^^^^^^^^^^^^^^^^^^^^^
  File "/home/igoriusha/.virtualenvs/.venv/lib/python3.12/site-packages/django/utils/decorators.py", line 48, in _wrapper
    return bound_method(*args, **kwargs)
           ^^^^^^^^^^^^^^^^^^^^^^^^^^^^^
  File "/home/igoriusha/.virtualenvs/.venv/lib/python3.12/site-packages/django/utils/decorators.py", line 188, in _view_wrapper
    result = _process_exception(request, e)
             ^^^^^^^^^^^^^^^^^^^^^^^^^^^^^^
  File "/home/igoriusha/.virtualenvs/.venv/lib/python3.12/site-packages/django/utils/decorators.py", line 186, in _view_wrapper
    response = view_func(request, *args, **kwargs)
               ^^^^^^^^^^^^^^^^^^^^^^^^^^^^^^^^^^^
  File "/home/igoriusha/.virtualenvs/.venv/lib/python3.12/site-packages/django/contrib/admin/options.py", line 2140, in changelist_view
    "selection_note": _("0 of %(cnt)s selected") % {"cnt": len(cl.result_list)},
                                                           ^^^^^^^^^^^^^^^^^^^
  File "/home/igoriusha/.virtualenvs/.venv/lib/python3.12/site-packages/django/db/models/query.py", line 382, in __len__
    self._fetch_all()
  File "/home/igoriusha/.virtualenvs/.venv/lib/python3.12/site-packages/django/db/models/query.py", line 1928, in _fetch_all
    self._result_cache = list(self._iterable_class(self))
                         ^^^^^^^^^^^^^^^^^^^^^^^^^^^^^^^^
  File "/home/igoriusha/.virtualenvs/.venv/lib/python3.12/site-packages/django/db/models/query.py", line 91, in __iter__
    results = compiler.execute_sql(
              ^^^^^^^^^^^^^^^^^^^^^
  File "/home/igoriusha/.virtualenvs/.venv/lib/python3.12/site-packages/django/db/models/sql/compiler.py", line 1574, in execute_sql
    cursor.execute(sql, params)
  File "/home/igoriusha/.virtualenvs/.venv/lib/python3.12/site-packages/django/db/backends/utils.py", line 79, in execute
    return self._execute_with_wrappers(
           ^^^^^^^^^^^^^^^^^^^^^^^^^^^^
  File "/home/igoriusha/.virtualenvs/.venv/lib/python3.12/site-packages/django/db/backends/utils.py", line 92, in _execute_with_wrappers
    return executor(sql, params, many, context)
           ^^^^^^^^^^^^^^^^^^^^^^^^^^^^^^^^^^^^
  File "/home/igoriusha/.virtualenvs/.venv/lib/python3.12/site-packages/django/db/backends/utils.py", line 100, in _execute
    with self.db.wrap_database_errors:
  File "/home/igoriusha/.virtualenvs/.venv/lib/python3.12/site-packages/django/db/utils.py", line 91, in __exit__
    raise dj_exc_value.with_traceback(traceback) from exc_value
  File "/home/igoriusha/.virtualenvs/.venv/lib/python3.12/site-packages/django/db/backends/utils.py", line 105, in _execute
    return self.cursor.execute(sql, params)
           ^^^^^^^^^^^^^^^^^^^^^^^^^^^^^^^^
django.db.utils.ProgrammingError: column news_post.image does not exist
LINE 1: ..._post"."time_in_post", "news_post"."rating_post", "news_post...
                                                             ^

2025-04-14 22:25:07,374 ERROR /home/igoriusha/.virtualenvs/.venv/lib/python3.12/site-packages/django/core/servers/basehttp.py None "GET /admin/news/post/ HTTP/1.1" 500 7527
2025-04-14 22:35:49,799 ERROR /home/igoriusha/.virtualenvs/.venv/lib/python3.12/site-packages/django/utils/log.py (<class 'django.db.utils.ProgrammingError'>, ProgrammingError('column news_post.image does not exist\nLINE 1: ..._post"."time_in_post", "news_post"."rating_post", "news_post...\n                                                             ^\n'), <traceback object at 0x7e8208383f40>) Internal Server Error: /admin/news/comment/
Traceback (most recent call last):
  File "/home/igoriusha/.virtualenvs/.venv/lib/python3.12/site-packages/django/db/models/options.py", line 676, in get_field
    return self.fields_map[field_name]
           ~~~~~~~~~~~~~~~^^^^^^^^^^^^
KeyError: 'name_post'

During handling of the above exception, another exception occurred:

Traceback (most recent call last):
  File "/home/igoriusha/.virtualenvs/.venv/lib/python3.12/site-packages/django/contrib/admin/utils.py", line 290, in lookup_field
    f = _get_non_gfk_field(opts, name)
        ^^^^^^^^^^^^^^^^^^^^^^^^^^^^^^
  File "/home/igoriusha/.virtualenvs/.venv/lib/python3.12/site-packages/django/contrib/admin/utils.py", line 330, in _get_non_gfk_field
    field = opts.get_field(name)
            ^^^^^^^^^^^^^^^^^^^^
  File "/home/igoriusha/.virtualenvs/.venv/lib/python3.12/site-packages/django/db/models/options.py", line 678, in get_field
    raise FieldDoesNotExist(
django.core.exceptions.FieldDoesNotExist: Comment has no field named 'name_post'

During handling of the above exception, another exception occurred:

Traceback (most recent call last):
  File "/home/igoriusha/.virtualenvs/.venv/lib/python3.12/site-packages/django/db/models/fields/related_descriptors.py", line 239, in __get__
    rel_obj = self.field.get_cached_value(instance)
              ^^^^^^^^^^^^^^^^^^^^^^^^^^^^^^^^^^^^^
  File "/home/igoriusha/.virtualenvs/.venv/lib/python3.12/site-packages/django/db/models/fields/mixins.py", line 37, in get_cached_value
    return instance._state.fields_cache[self.cache_name]
           ~~~~~~~~~~~~~~~~~~~~~~~~~~~~^^^^^^^^^^^^^^^^^
KeyError: 'post_comment'

During handling of the above exception, another exception occurred:

Traceback (most recent call last):
  File "/home/igoriusha/.virtualenvs/.venv/lib/python3.12/site-packages/django/db/backends/utils.py", line 105, in _execute
    return self.cursor.execute(sql, params)
           ^^^^^^^^^^^^^^^^^^^^^^^^^^^^^^^^
psycopg2.errors.UndefinedColumn: column news_post.image does not exist
LINE 1: ..._post"."time_in_post", "news_post"."rating_post", "news_post...
                                                             ^


The above exception was the direct cause of the following exception:

Traceback (most recent call last):
  File "/home/igoriusha/.virtualenvs/.venv/lib/python3.12/site-packages/django/core/handlers/exception.py", line 55, in inner
    response = get_response(request)
               ^^^^^^^^^^^^^^^^^^^^^
  File "/home/igoriusha/.virtualenvs/.venv/lib/python3.12/site-packages/django/core/handlers/base.py", line 220, in _get_response
    response = response.render()
               ^^^^^^^^^^^^^^^^^
  File "/home/igoriusha/.virtualenvs/.venv/lib/python3.12/site-packages/django/template/response.py", line 114, in render
    self.content = self.rendered_content
                   ^^^^^^^^^^^^^^^^^^^^^
  File "/home/igoriusha/.virtualenvs/.venv/lib/python3.12/site-packages/django/template/response.py", line 92, in rendered_content
    return template.render(context, self._request)
           ^^^^^^^^^^^^^^^^^^^^^^^^^^^^^^^^^^^^^^^
  File "/home/igoriusha/.virtualenvs/.venv/lib/python3.12/site-packages/django/template/backends/django.py", line 107, in render
    return self.template.render(context)
           ^^^^^^^^^^^^^^^^^^^^^^^^^^^^^
  File "/home/igoriusha/.virtualenvs/.venv/lib/python3.12/site-packages/django/template/base.py", line 171, in render
    return self._render(context)
           ^^^^^^^^^^^^^^^^^^^^^
  File "/home/igoriusha/.virtualenvs/.venv/lib/python3.12/site-packages/django/template/base.py", line 163, in _render
    return self.nodelist.render(context)
           ^^^^^^^^^^^^^^^^^^^^^^^^^^^^^
  File "/home/igoriusha/.virtualenvs/.venv/lib/python3.12/site-packages/django/template/base.py", line 1008, in render
    return SafeString("".join([node.render_annotated(context) for node in self]))
                               ^^^^^^^^^^^^^^^^^^^^^^^^^^^^^^
  File "/home/igoriusha/.virtualenvs/.venv/lib/python3.12/site-packages/django/template/base.py", line 969, in render_annotated
    return self.render(context)
           ^^^^^^^^^^^^^^^^^^^^
  File "/home/igoriusha/.virtualenvs/.venv/lib/python3.12/site-packages/django/template/loader_tags.py", line 159, in render
    return compiled_parent._render(context)
           ^^^^^^^^^^^^^^^^^^^^^^^^^^^^^^^^
  File "/home/igoriusha/.virtualenvs/.venv/lib/python3.12/site-packages/django/template/base.py", line 163, in _render
    return self.nodelist.render(context)
           ^^^^^^^^^^^^^^^^^^^^^^^^^^^^^
  File "/home/igoriusha/.virtualenvs/.venv/lib/python3.12/site-packages/django/template/base.py", line 1008, in render
    return SafeString("".join([node.render_annotated(context) for node in self]))
                               ^^^^^^^^^^^^^^^^^^^^^^^^^^^^^^
  File "/home/igoriusha/.virtualenvs/.venv/lib/python3.12/site-packages/django/template/base.py", line 969, in render_annotated
    return self.render(context)
           ^^^^^^^^^^^^^^^^^^^^
  File "/home/igoriusha/.virtualenvs/.venv/lib/python3.12/site-packages/django/template/loader_tags.py", line 159, in render
    return compiled_parent._render(context)
           ^^^^^^^^^^^^^^^^^^^^^^^^^^^^^^^^
  File "/home/igoriusha/.virtualenvs/.venv/lib/python3.12/site-packages/django/template/base.py", line 163, in _render
    return self.nodelist.render(context)
           ^^^^^^^^^^^^^^^^^^^^^^^^^^^^^
  File "/home/igoriusha/.virtualenvs/.venv/lib/python3.12/site-packages/django/template/base.py", line 1008, in render
    return SafeString("".join([node.render_annotated(context) for node in self]))
                               ^^^^^^^^^^^^^^^^^^^^^^^^^^^^^^
  File "/home/igoriusha/.virtualenvs/.venv/lib/python3.12/site-packages/django/template/base.py", line 969, in render_annotated
    return self.render(context)
           ^^^^^^^^^^^^^^^^^^^^
  File "/home/igoriusha/.virtualenvs/.venv/lib/python3.12/site-packages/django/template/loader_tags.py", line 65, in render
    result = block.nodelist.render(context)
             ^^^^^^^^^^^^^^^^^^^^^^^^^^^^^^
  File "/home/igoriusha/.virtualenvs/.venv/lib/python3.12/site-packages/django/template/base.py", line 1008, in render
    return SafeString("".join([node.render_annotated(context) for node in self]))
                               ^^^^^^^^^^^^^^^^^^^^^^^^^^^^^^
  File "/home/igoriusha/.virtualenvs/.venv/lib/python3.12/site-packages/django/template/base.py", line 969, in render_annotated
    return self.render(context)
           ^^^^^^^^^^^^^^^^^^^^
  File "/home/igoriusha/.virtualenvs/.venv/lib/python3.12/site-packages/django/template/loader_tags.py", line 65, in render
    result = block.nodelist.render(context)
             ^^^^^^^^^^^^^^^^^^^^^^^^^^^^^^
  File "/home/igoriusha/.virtualenvs/.venv/lib/python3.12/site-packages/django/template/base.py", line 1008, in render
    return SafeString("".join([node.render_annotated(context) for node in self]))
                               ^^^^^^^^^^^^^^^^^^^^^^^^^^^^^^
  File "/home/igoriusha/.virtualenvs/.venv/lib/python3.12/site-packages/django/template/base.py", line 969, in render_annotated
    return self.render(context)
           ^^^^^^^^^^^^^^^^^^^^
  File "/home/igoriusha/.virtualenvs/.venv/lib/python3.12/site-packages/django/contrib/admin/templatetags/base.py", line 45, in render
    return super().render(context)
           ^^^^^^^^^^^^^^^^^^^^^^^
  File "/home/igoriusha/.virtualenvs/.venv/lib/python3.12/site-packages/django/template/library.py", line 258, in render
    _dict = self.func(*resolved_args, **resolved_kwargs)
            ^^^^^^^^^^^^^^^^^^^^^^^^^^^^^^^^^^^^^^^^^^^^
  File "/home/igoriusha/.virtualenvs/.venv/lib/python3.12/site-packages/django/contrib/admin/templatetags/admin_list.py", line 346, in result_list
    "results": list(results(cl)),
               ^^^^^^^^^^^^^^^^^
  File "/home/igoriusha/.virtualenvs/.venv/lib/python3.12/site-packages/django/contrib/admin/templatetags/admin_list.py", line 322, in results
    yield ResultList(None, items_for_result(cl, res, None))
          ^^^^^^^^^^^^^^^^^^^^^^^^^^^^^^^^^^^^^^^^^^^^^^^^^
  File "/home/igoriusha/.virtualenvs/.venv/lib/python3.12/site-packages/django/contrib/admin/templatetags/admin_list.py", line 313, in __init__
    super().__init__(*items)
  File "/home/igoriusha/.virtualenvs/.venv/lib/python3.12/site-packages/django/contrib/admin/templatetags/admin_list.py", line 218, in items_for_result
    f, attr, value = lookup_field(field_name, result, cl.model_admin)
                     ^^^^^^^^^^^^^^^^^^^^^^^^^^^^^^^^^^^^^^^^^^^^^^^^
  File "/home/igoriusha/.virtualenvs/.venv/lib/python3.12/site-packages/django/contrib/admin/utils.py", line 299, in lookup_field
    value = attr(obj)
            ^^^^^^^^^
  File "/home/igoriusha/MyProject/Portal_News/NewsPaper/news/admin.py", line 298, in name_post
    return obj.preview(obj.post_comment.title_post)
                       ^^^^^^^^^^^^^^^^
  File "/home/igoriusha/.virtualenvs/.venv/lib/python3.12/site-packages/django/db/models/fields/related_descriptors.py", line 257, in __get__
    rel_obj = self.get_object(instance)
              ^^^^^^^^^^^^^^^^^^^^^^^^^
  File "/home/igoriusha/.virtualenvs/.venv/lib/python3.12/site-packages/django/db/models/fields/related_descriptors.py", line 220, in get_object
    return qs.get(self.field.get_reverse_related_filter(instance))
           ^^^^^^^^^^^^^^^^^^^^^^^^^^^^^^^^^^^^^^^^^^^^^^^^^^^^^^^
  File "/home/igoriusha/.virtualenvs/.venv/lib/python3.12/site-packages/django/db/models/query.py", line 645, in get
    num = len(clone)
          ^^^^^^^^^^
  File "/home/igoriusha/.virtualenvs/.venv/lib/python3.12/site-packages/django/db/models/query.py", line 382, in __len__
    self._fetch_all()
  File "/home/igoriusha/.virtualenvs/.venv/lib/python3.12/site-packages/django/db/models/query.py", line 1928, in _fetch_all
    self._result_cache = list(self._iterable_class(self))
                         ^^^^^^^^^^^^^^^^^^^^^^^^^^^^^^^^
  File "/home/igoriusha/.virtualenvs/.venv/lib/python3.12/site-packages/django/db/models/query.py", line 91, in __iter__
    results = compiler.execute_sql(
              ^^^^^^^^^^^^^^^^^^^^^
  File "/home/igoriusha/.virtualenvs/.venv/lib/python3.12/site-packages/django/db/models/sql/compiler.py", line 1574, in execute_sql
    cursor.execute(sql, params)
  File "/home/igoriusha/.virtualenvs/.venv/lib/python3.12/site-packages/django/db/backends/utils.py", line 79, in execute
    return self._execute_with_wrappers(
           ^^^^^^^^^^^^^^^^^^^^^^^^^^^^
  File "/home/igoriusha/.virtualenvs/.venv/lib/python3.12/site-packages/django/db/backends/utils.py", line 92, in _execute_with_wrappers
    return executor(sql, params, many, context)
           ^^^^^^^^^^^^^^^^^^^^^^^^^^^^^^^^^^^^
  File "/home/igoriusha/.virtualenvs/.venv/lib/python3.12/site-packages/django/db/backends/utils.py", line 100, in _execute
    with self.db.wrap_database_errors:
  File "/home/igoriusha/.virtualenvs/.venv/lib/python3.12/site-packages/django/db/utils.py", line 91, in __exit__
    raise dj_exc_value.with_traceback(traceback) from exc_value
  File "/home/igoriusha/.virtualenvs/.venv/lib/python3.12/site-packages/django/db/backends/utils.py", line 105, in _execute
    return self.cursor.execute(sql, params)
           ^^^^^^^^^^^^^^^^^^^^^^^^^^^^^^^^
django.db.utils.ProgrammingError: column news_post.image does not exist
LINE 1: ..._post"."time_in_post", "news_post"."rating_post", "news_post...
                                                             ^

2025-04-14 22:35:49,805 ERROR /home/igoriusha/.virtualenvs/.venv/lib/python3.12/site-packages/django/core/servers/basehttp.py None "GET /admin/news/comment/ HTTP/1.1" 500 7527
2025-04-14 22:35:56,780 ERROR /home/igoriusha/.virtualenvs/.venv/lib/python3.12/site-packages/django/utils/log.py (<class 'django.db.utils.ProgrammingError'>, ProgrammingError('column news_post.image does not exist\nLINE 1: ..._post"."time_in_post", "news_post"."rating_post", "news_post...\n                                                             ^\n'), <traceback object at 0x7e8206ef9f00>) Internal Server Error: /admin/news/post/
Traceback (most recent call last):
  File "/home/igoriusha/.virtualenvs/.venv/lib/python3.12/site-packages/django/db/backends/utils.py", line 105, in _execute
    return self.cursor.execute(sql, params)
           ^^^^^^^^^^^^^^^^^^^^^^^^^^^^^^^^
psycopg2.errors.UndefinedColumn: column news_post.image does not exist
LINE 1: ..._post"."time_in_post", "news_post"."rating_post", "news_post...
                                                             ^


The above exception was the direct cause of the following exception:

Traceback (most recent call last):
  File "/home/igoriusha/.virtualenvs/.venv/lib/python3.12/site-packages/django/core/handlers/exception.py", line 55, in inner
    response = get_response(request)
               ^^^^^^^^^^^^^^^^^^^^^
  File "/home/igoriusha/.virtualenvs/.venv/lib/python3.12/site-packages/django/core/handlers/base.py", line 197, in _get_response
    response = wrapped_callback(request, *callback_args, **callback_kwargs)
               ^^^^^^^^^^^^^^^^^^^^^^^^^^^^^^^^^^^^^^^^^^^^^^^^^^^^^^^^^^^^
  File "/home/igoriusha/.virtualenvs/.venv/lib/python3.12/site-packages/django/contrib/admin/options.py", line 718, in wrapper
    return self.admin_site.admin_view(view)(*args, **kwargs)
           ^^^^^^^^^^^^^^^^^^^^^^^^^^^^^^^^^^^^^^^^^^^^^^^^^
  File "/home/igoriusha/.virtualenvs/.venv/lib/python3.12/site-packages/django/utils/decorators.py", line 188, in _view_wrapper
    result = _process_exception(request, e)
             ^^^^^^^^^^^^^^^^^^^^^^^^^^^^^^
  File "/home/igoriusha/.virtualenvs/.venv/lib/python3.12/site-packages/django/utils/decorators.py", line 186, in _view_wrapper
    response = view_func(request, *args, **kwargs)
               ^^^^^^^^^^^^^^^^^^^^^^^^^^^^^^^^^^^
  File "/home/igoriusha/.virtualenvs/.venv/lib/python3.12/site-packages/django/views/decorators/cache.py", line 80, in _view_wrapper
    response = view_func(request, *args, **kwargs)
               ^^^^^^^^^^^^^^^^^^^^^^^^^^^^^^^^^^^
  File "/home/igoriusha/.virtualenvs/.venv/lib/python3.12/site-packages/django/contrib/admin/sites.py", line 241, in inner
    return view(request, *args, **kwargs)
           ^^^^^^^^^^^^^^^^^^^^^^^^^^^^^^
  File "/home/igoriusha/.virtualenvs/.venv/lib/python3.12/site-packages/django/utils/decorators.py", line 48, in _wrapper
    return bound_method(*args, **kwargs)
           ^^^^^^^^^^^^^^^^^^^^^^^^^^^^^
  File "/home/igoriusha/.virtualenvs/.venv/lib/python3.12/site-packages/django/utils/decorators.py", line 188, in _view_wrapper
    result = _process_exception(request, e)
             ^^^^^^^^^^^^^^^^^^^^^^^^^^^^^^
  File "/home/igoriusha/.virtualenvs/.venv/lib/python3.12/site-packages/django/utils/decorators.py", line 186, in _view_wrapper
    response = view_func(request, *args, **kwargs)
               ^^^^^^^^^^^^^^^^^^^^^^^^^^^^^^^^^^^
  File "/home/igoriusha/.virtualenvs/.venv/lib/python3.12/site-packages/django/contrib/admin/options.py", line 2140, in changelist_view
    "selection_note": _("0 of %(cnt)s selected") % {"cnt": len(cl.result_list)},
                                                           ^^^^^^^^^^^^^^^^^^^
  File "/home/igoriusha/.virtualenvs/.venv/lib/python3.12/site-packages/django/db/models/query.py", line 382, in __len__
    self._fetch_all()
  File "/home/igoriusha/.virtualenvs/.venv/lib/python3.12/site-packages/django/db/models/query.py", line 1928, in _fetch_all
    self._result_cache = list(self._iterable_class(self))
                         ^^^^^^^^^^^^^^^^^^^^^^^^^^^^^^^^
  File "/home/igoriusha/.virtualenvs/.venv/lib/python3.12/site-packages/django/db/models/query.py", line 91, in __iter__
    results = compiler.execute_sql(
              ^^^^^^^^^^^^^^^^^^^^^
  File "/home/igoriusha/.virtualenvs/.venv/lib/python3.12/site-packages/django/db/models/sql/compiler.py", line 1574, in execute_sql
    cursor.execute(sql, params)
  File "/home/igoriusha/.virtualenvs/.venv/lib/python3.12/site-packages/django/db/backends/utils.py", line 79, in execute
    return self._execute_with_wrappers(
           ^^^^^^^^^^^^^^^^^^^^^^^^^^^^
  File "/home/igoriusha/.virtualenvs/.venv/lib/python3.12/site-packages/django/db/backends/utils.py", line 92, in _execute_with_wrappers
    return executor(sql, params, many, context)
           ^^^^^^^^^^^^^^^^^^^^^^^^^^^^^^^^^^^^
  File "/home/igoriusha/.virtualenvs/.venv/lib/python3.12/site-packages/django/db/backends/utils.py", line 100, in _execute
    with self.db.wrap_database_errors:
  File "/home/igoriusha/.virtualenvs/.venv/lib/python3.12/site-packages/django/db/utils.py", line 91, in __exit__
    raise dj_exc_value.with_traceback(traceback) from exc_value
  File "/home/igoriusha/.virtualenvs/.venv/lib/python3.12/site-packages/django/db/backends/utils.py", line 105, in _execute
    return self.cursor.execute(sql, params)
           ^^^^^^^^^^^^^^^^^^^^^^^^^^^^^^^^
django.db.utils.ProgrammingError: column news_post.image does not exist
LINE 1: ..._post"."time_in_post", "news_post"."rating_post", "news_post...
                                                             ^

2025-04-14 22:35:56,784 ERROR /home/igoriusha/.virtualenvs/.venv/lib/python3.12/site-packages/django/core/servers/basehttp.py None "GET /admin/news/post/ HTTP/1.1" 500 7527
